Workbook

Sheet Overview
A1: CloudBench | Research overview
A2: SIMULATED DATA – NOT REAL CLOUD MEASUREMENTS
A3: Cohort selectors: A4 scenario; B4 load; C4 endpoint. H4 cost level. Only valid independent runs.
A4: steady | B4: medium | C4: all | H4: medium
A5: Model | B5: Valid runs | C5: Mean run p50 (ms) | D5: Mean run p95 (ms) | E5: Mean run p99 (ms) | F5: Throughput (req/s) | G5: Error rate (%) | H5: Monthly cost (USD) | I5: Capacity status
A6: IAAS | B6: =COUNTIFS('Per Run'!$C$6:$C$304,LOWER(A6),'Per Run'!$D$6:$D$304,$A$4,'Per Run'!$E$6:$E$304,$B$4,'Per Run'!$F$6:$F$304,$C$4,'Per Run'!$AE$6:$AE$304,TRUE) -> 5 | C6: =IFERROR(AVERAGEIFS('Per Run'!$M$6:$M$304,'Per Run'!$C$6:$C$304,LOWER(A6),'Per Run'!$D$6:$D$304,$A$4,'Per Run'!$E$6:$E$304,$B$4,'Per Run'!$F$6:$F$304,$C$4,'Per Run'!$AE$6:$AE$304,TRUE),"N/A") -> 36.996008 | D6: =IFERROR(AVERAGEIFS('Per Run'!$N$6:$N$304,'Per Run'!$C$6:$C$304,LOWER(A6),'Per Run'!$D$6:$D$304,$A$4,'Per Run'!$E$6:$E$304,$B$4,'Per Run'!$F$6:$F$304,$C$4,'Per Run'!$AE$6:$AE$304,TRUE),"N/A") -> 104.96013 | E6: =IFERROR(AVERAGEIFS('Per Run'!$O$6:$O$304,'Per Run'!$C$6:$C$304,LOWER(A6),'Per Run'!$D$6:$D$304,$A$4,'Per Run'!$E$6:$E$304,$B$4,'Per Run'!$F$6:$F$304,$C$4,'Per Run'!$AE$6:$AE$304,TRUE),"N/A") -> 173.32995 | F6: =IFERROR(AVERAGEIFS('Per Run'!$V$6:$V$304,'Per Run'!$C$6:$C$304,LOWER(A6),'Per Run'!$D$6:$D$304,$A$4,'Per Run'!$E$6:$E$304,$B$4,'Per Run'!$F$6:$F$304,$C$4,'Per Run'!$AE$6:$AE$304,TRUE),"N/A") -> 19.966667 | G6: =IFERROR(AVERAGEIFS('Per Run'!$Y$6:$Y$304,'Per Run'!$C$6:$C$304,LOWER(A6),'Per Run'!$D$6:$D$304,$A$4,'Per Run'!$E$6:$E$304,$B$4,'Per Run'!$F$6:$F$304,$C$4,'Per Run'!$AE$6:$AE$304,TRUE),"N/A") -> 1.3888889 | H6: =SUMIFS('Cost Summary'!$J$6:$J$14,'Cost Summary'!$A$6:$A$14,$H$4,'Cost Summary'!$B$6:$B$14,LOWER(A6)) -> 61.930282 | I6: =IFERROR(INDEX('Cost Summary'!$I$6:$I$14,MATCH($H$4&"|"&LOWER(A6),'Cost Summary'!$M$6:$M$14,0)),"N/A") -> UNVERIFIED
A7: PAAS | B7: =COUNTIFS('Per Run'!$C$6:$C$304,LOWER(A7),'Per Run'!$D$6:$D$304,$A$4,'Per Run'!$E$6:$E$304,$B$4,'Per Run'!$F$6:$F$304,$C$4,'Per Run'!$AE$6:$AE$304,TRUE) -> 5 | C7: =IFERROR(AVERAGEIFS('Per Run'!$M$6:$M$304,'Per Run'!$C$6:$C$304,LOWER(A7),'Per Run'!$D$6:$D$304,$A$4,'Per Run'!$E$6:$E$304,$B$4,'Per Run'!$F$6:$F$304,$C$4,'Per Run'!$AE$6:$AE$304,TRUE),"N/A") -> 39.380918 | D7: =IFERROR(AVERAGEIFS('Per Run'!$N$6:$N$304,'Per Run'!$C$6:$C$304,LOWER(A7),'Per Run'!$D$6:$D$304,$A$4,'Per Run'!$E$6:$E$304,$B$4,'Per Run'!$F$6:$F$304,$C$4,'Per Run'!$AE$6:$AE$304,TRUE),"N/A") -> 112.62468 | E7: =IFERROR(AVERAGEIFS('Per Run'!$O$6:$O$304,'Per Run'!$C$6:$C$304,LOWER(A7),'Per Run'!$D$6:$D$304,$A$4,'Per Run'!$E$6:$E$304,$B$4,'Per Run'!$F$6:$F$304,$C$4,'Per Run'!$AE$6:$AE$304,TRUE),"N/A") -> 223.80003 | F7: =IFERROR(AVERAGEIFS('Per Run'!$V$6:$V$304,'Per Run'!$C$6:$C$304,LOWER(A7),'Per Run'!$D$6:$D$304,$A$4,'Per Run'!$E$6:$E$304,$B$4,'Per Run'!$F$6:$F$304,$C$4,'Per Run'!$AE$6:$AE$304,TRUE),"N/A") -> 19.988889 | G7: =IFERROR(AVERAGEIFS('Per Run'!$Y$6:$Y$304,'Per Run'!$C$6:$C$304,LOWER(A7),'Per Run'!$D$6:$D$304,$A$4,'Per Run'!$E$6:$E$304,$B$4,'Per Run'!$F$6:$F$304,$C$4,'Per Run'!$AE$6:$AE$304,TRUE),"N/A") -> 1.4444444 | H7: =SUMIFS('Cost Summary'!$J$6:$J$14,'Cost Summary'!$A$6:$A$14,$H$4,'Cost Summary'!$B$6:$B$14,LOWER(A7)) -> 8.9718688 | I7: =IFERROR(INDEX('Cost Summary'!$I$6:$I$14,MATCH($H$4&"|"&LOWER(A7),'Cost Summary'!$M$6:$M$14,0)),"N/A") -> ESTIMATED_SUPPORTED
A8: FAAS | B8: =COUNTIFS('Per Run'!$C$6:$C$304,LOWER(A8),'Per Run'!$D$6:$D$304,$A$4,'Per Run'!$E$6:$E$304,$B$4,'Per Run'!$F$6:$F$304,$C$4,'Per Run'!$AE$6:$AE$304,TRUE) -> 5 | C8: =IFERROR(AVERAGEIFS('Per Run'!$M$6:$M$304,'Per Run'!$C$6:$C$304,LOWER(A8),'Per Run'!$D$6:$D$304,$A$4,'Per Run'!$E$6:$E$304,$B$4,'Per Run'!$F$6:$F$304,$C$4,'Per Run'!$AE$6:$AE$304,TRUE),"N/A") -> 37.735715 | D8: =IFERROR(AVERAGEIFS('Per Run'!$N$6:$N$304,'Per Run'!$C$6:$C$304,LOWER(A8),'Per Run'!$D$6:$D$304,$A$4,'Per Run'!$E$6:$E$304,$B$4,'Per Run'!$F$6:$F$304,$C$4,'Per Run'!$AE$6:$AE$304,TRUE),"N/A") -> 105.32929 | E8: =IFERROR(AVERAGEIFS('Per Run'!$O$6:$O$304,'Per Run'!$C$6:$C$304,LOWER(A8),'Per Run'!$D$6:$D$304,$A$4,'Per Run'!$E$6:$E$304,$B$4,'Per Run'!$F$6:$F$304,$C$4,'Per Run'!$AE$6:$AE$304,TRUE),"N/A") -> 165.78197 | F8: =IFERROR(AVERAGEIFS('Per Run'!$V$6:$V$304,'Per Run'!$C$6:$C$304,LOWER(A8),'Per Run'!$D$6:$D$304,$A$4,'Per Run'!$E$6:$E$304,$B$4,'Per Run'!$F$6:$F$304,$C$4,'Per Run'!$AE$6:$AE$304,TRUE),"N/A") -> 20 | G8: =IFERROR(AVERAGEIFS('Per Run'!$Y$6:$Y$304,'Per Run'!$C$6:$C$304,LOWER(A8),'Per Run'!$D$6:$D$304,$A$4,'Per Run'!$E$6:$E$304,$B$4,'Per Run'!$F$6:$F$304,$C$4,'Per Run'!$AE$6:$AE$304,TRUE),"N/A") -> 1.7777778 | H8: =SUMIFS('Cost Summary'!$J$6:$J$14,'Cost Summary'!$A$6:$A$14,$H$4,'Cost Summary'!$B$6:$B$14,LOWER(A8)) -> 8.9718688 | I8: =IFERROR(INDEX('Cost Summary'!$I$6:$I$14,MATCH($H$4&"|"&LOWER(A8),'Cost Summary'!$M$6:$M$14,0)),"N/A") -> ESTIMATED_SUPPORTED
A10: INCONCLUSIVE for empirical GCP conclusions in DEMO. Capacity is a separate requirement; latency and cost have different scopes.
A37: Bảng nguồn đầy đủ ở Per Run / Confidence; không dùng biểu đồ mean như kiểm định thống kê.

Sheet Per Run
A1: Per Run
A2: SIMULATED DATA – NOT REAL CLOUD MEASUREMENTS
A3: results\processed\demo\per_run.csv
A5: data_mode | B5: run_id | C5: model | D5: scenario | E5: load_level | F5: endpoint | G5: repeat | H5: request_count | I5: success_count | J5: failure_count | K5: unknown_outcome_count | L5: mean_ms | M5: p50_ms | N5: p95_ms | O5: p99_ms | P5: min_ms | Q5: max_ms | R5: std_ms | S5: cv | T5: duration_seconds | U5: offered_rps | V5: achieved_rps | W5: cohort_rps | X5: goodput_rps | Y5: error_rate_pct | Z5: dropped_iterations | AA5: dropped_rate_pct | AB5: cold_count | AC5: cold_ratio_pct | AD5: unknown_classification_count | AE5: valid_for_comparison | AF5: status | AG5: p99_warning | AH5: warning
A6: DEMO | B6: simulated-faas-burst-burst-mixed-r01 | C6: faas | D6: burst | E6: burst | F6: all | G6: 1 | H6: 830 | I6: 817 | J6: 13 | K6: 0 | L6: 75.594245 | M6: 60.30029 | N6: 172.47119 | O6: 252.8246 | P6: 15.696553 | Q6: 1488.7454 | R6: 68.439908 | S6: 0.90535871 | T6: 20 | U6: 41.5 | V6: 41.5 | W6: 41.5 | X6: 40.85 | Y6: 1.5662651 | Z6: 0 | AA6: 0 | AB6: 0 | AC6: 0 | AD6: 43 | AE6: TRUE | AF6: COMPLETE | AG6: UNSTABLE_SMALL_SAMPLE
A7: DEMO | B7: simulated-faas-burst-burst-mixed-r01 | C7: faas | D7: burst | E7: burst | F7: cpu | G7: 1 | H7: 83 | I7: 82 | J7: 1 | K7: 0 | L7: 180.45591 | M7: 158.45627 | N7: 262.30618 | O7: 581.25835 | P7: 51.196236 | Q7: 1488.7454 | R7: 157.9181 | S7: 0.87510628 | T7: 20 | U7: 4.15 | V7: 4.15 | W7: 4.15 | X7: 4.1 | Y7: 1.2048193 | AB7: 0 | AC7: 0 | AD7: 3 | AE7: TRUE | AF7: COMPLETE | AG7: UNSTABLE_SMALL_SAMPLE
A8: DEMO | B8: simulated-faas-burst-burst-mixed-r01 | C8: faas | D8: burst | E8: burst | F8: read | G8: 1 | H8: 586 | I8: 577 | J8: 9 | K8: 0 | L8: 58.008621 | M8: 53.407455 | N8: 102.7781 | O8: 121.36719 | P8: 15.696553 | Q8: 498.52723 | R8: 29.058782 | S8: 0.50093902 | T8: 20 | U8: 29.05 | V8: 29.3 | W8: 29.3 | X8: 28.85 | Y8: 1.5358362 | AB8: 0 | AC8: 0 | AD8: 34 | AE8: TRUE | AF8: COMPLETE | AG8: UNSTABLE_SMALL_SAMPLE
A9: DEMO | B9: simulated-faas-burst-burst-mixed-r01 | C9: faas | D9: burst | E9: burst | F9: write | G9: 1 | H9: 161 | I9: 158 | J9: 3 | K9: 0 | L9: 85.542427 | M9: 78.590468 | N9: 161.04107 | O9: 199.79074 | P9: 25.392753 | Q9: 241.75394 | R9: 38.26909 | S9: 0.4473697 | T9: 20 | U9: 8.3 | V9: 8.05 | W9: 8.05 | X9: 7.9 | Y9: 1.863354 | AB9: 0 | AC9: 0 | AD9: 6 | AE9: TRUE | AF9: COMPLETE | AG9: UNSTABLE_SMALL_SAMPLE
A10: DEMO | B10: simulated-faas-burst-burst-mixed-r02 | C10: faas | D10: burst | E10: burst | F10: all | G10: 2 | H10: 830 | I10: 819 | J10: 11 | K10: 0 | L10: 61.503221 | M10: 48.221026 | N10: 137.76545 | O10: 252.33866 | P10: 11.806276 | Q10: 587.50153 | R10: 49.986968 | S10: 0.81275366 | T10: 20 | U10: 41.5 | V10: 41.5 | W10: 41.5 | X10: 40.95 | Y10: 1.3253012 | Z10: 0 | AA10: 0 | AB10: 0 | AC10: 0 | AD10: 41 | AE10: TRUE | AF10: COMPLETE | AG10: UNSTABLE_SMALL_SAMPLE
A11: DEMO | B11: simulated-faas-burst-burst-mixed-r02 | C11: faas | D11: burst | E11: burst | F11: cpu | G11: 2 | H11: 84 | I11: 83 | J11: 1 | K11: 0 | L11: 146.57061 | M11: 127.01131 | N11: 280.99287 | O11: 376.00366 | P11: 56.410148 | Q11: 505.28224 | R11: 74.546858 | S11: 0.50860714 | T11: 20 | U11: 4.15 | V11: 4.2 | W11: 4.2 | X11: 4.15 | Y11: 1.1904762 | AB11: 0 | AC11: 0 | AD11: 8 | AE11: TRUE | AF11: COMPLETE | AG11: UNSTABLE_SMALL_SAMPLE
A12: DEMO | B12: simulated-faas-burst-burst-mixed-r02 | C12: faas | D12: burst | E12: burst | F12: read | G12: 2 | H12: 575 | I12: 570 | J12: 5 | K12: 0 | L12: 47.260514 | M12: 41.128759 | N12: 79.749278 | O12: 109.67899 | P12: 11.806276 | Q12: 587.50153 | R12: 35.775338 | S12: 0.75698156 | T12: 20 | U12: 29.05 | V12: 28.75 | W12: 28.75 | X12: 28.5 | Y12: 0.86956522 | AB12: 0 | AC12: 0 | AD12: 29 | AE12: TRUE | AF12: COMPLETE | AG12: UNSTABLE_SMALL_SAMPLE
A13: DEMO | B13: simulated-faas-burst-burst-mixed-r02 | C13: faas | D13: burst | E13: burst | F13: write | G13: 2 | H13: 171 | I13: 166 | J13: 5 | K13: 0 | L13: 67.607875 | M13: 61.843339 | N13: 125.51231 | O13: 176.17127 | P13: 21.749134 | Q13: 182.91678 | R13: 29.169334 | S13: 0.43144877 | T13: 20 | U13: 8.3 | V13: 8.55 | W13: 8.55 | X13: 8.3 | Y13: 2.9239766 | AB13: 0 | AC13: 0 | AD13: 4 | AE13: TRUE | AF13: COMPLETE | AG13: UNSTABLE_SMALL_SAMPLE
A14: DEMO | B14: simulated-faas-burst-burst-mixed-r03 | C14: faas | D14: burst | E14: burst | F14: all | G14: 3 | H14: 830 | I14: 815 | J14: 15 | K14: 0 | L14: 76.625614 | M14: 59.562369 | N14: 171.92935 | O14: 308.78726 | P14: 13.574096 | Q14: 932.97067 | R14: 72.149367 | S14: 0.94158289 | T14: 20 | U14: 41.5 | V14: 41.5 | W14: 41.5 | X14: 40.75 | Y14: 1.8072289 | Z14: 0 | AA14: 0 | AB14: 0 | AC14: 0 | AD14: 57 | AE14: TRUE | AF14: COMPLETE | AG14: UNSTABLE_SMALL_SAMPLE
A15: DEMO | B15: simulated-faas-burst-burst-mixed-r03 | C15: faas | D15: burst | E15: burst | F15: cpu | G15: 3 | H15: 90 | I15: 88 | J15: 2 | K15: 0 | L15: 157.34514 | M15: 149.09363 | N15: 280.74705 | O15: 339.52251 | P15: 61.672689 | Q15: 356.13958 | R15: 61.684467 | S15: 0.39203287 | T15: 20 | U15: 4.15 | V15: 4.5 | W15: 4.5 | X15: 4.4 | Y15: 2.2222222 | AB15: 0 | AC15: 0 | AD15: 6 | AE15: TRUE | AF15: COMPLETE | AG15: UNSTABLE_SMALL_SAMPLE
A16: DEMO | B16: simulated-faas-burst-burst-mixed-r03 | C16: faas | D16: burst | E16: burst | F16: read | G16: 3 | H16: 568 | I16: 558 | J16: 10 | K16: 0 | L16: 61.768472 | M16: 49.74793 | N16: 101.14199 | O16: 249.67205 | P16: 13.574096 | Q16: 932.97067 | R16: 73.484645 | S16: 1.1896789 | T16: 20 | U16: 29.05 | V16: 28.4 | W16: 28.4 | X16: 27.9 | Y16: 1.7605634 | AB16: 0 | AC16: 0 | AD16: 37 | AE16: TRUE | AF16: COMPLETE | AG16: UNSTABLE_SMALL_SAMPLE
A17: DEMO | B17: simulated-faas-burst-burst-mixed-r03 | C17: faas | D17: burst | E17: burst | F17: write | G17: 3 | H17: 172 | I17: 169 | J17: 3 | K17: 0 | L17: 83.451773 | M17: 77.160097 | N17: 142.87436 | O17: 185.45091 | P17: 21.631114 | Q17: 221.40202 | R17: 33.781809 | S17: 0.40480636 | T17: 20 | U17: 8.3 | V17: 8.6 | W17: 8.6 | X17: 8.45 | Y17: 1.744186 | AB17: 0 | AC17: 0 | AD17: 14 | AE17: TRUE | AF17: COMPLETE | AG17: UNSTABLE_SMALL_SAMPLE
A18: DEMO | B18: simulated-faas-burst-burst-mixed-r04 | C18: faas | D18: burst | E18: burst | F18: all | G18: 4 | H18: 830 | I18: 822 | J18: 8 | K18: 0 | L18: 64.593328 | M18: 48.647238 | N18: 148.37239 | O18: 247.64716 | P18: 13.85325 | Q18: 1702.56 | R18: 77.429398 | S18: 1.1987213 | T18: 20 | U18: 41.5 | V18: 41.5 | W18: 41.5 | X18: 41.1 | Y18: 0.96385542 | Z18: 0 | AA18: 0 | AB18: 0 | AC18: 0 | AD18: 30 | AE18: TRUE | AF18: COMPLETE | AG18: UNSTABLE_SMALL_SAMPLE
A19: DEMO | B19: simulated-faas-burst-burst-mixed-r04 | C19: faas | D19: burst | E19: burst | F19: cpu | G19: 4 | H19: 96 | I19: 95 | J19: 1 | K19: 0 | L19: 159.64623 | M19: 137.40863 | N19: 261.23805 | O19: 450.45181 | P19: 49.701554 | Q19: 1702.56 | R19: 171.07403 | S19: 1.0715821 | T19: 20 | U19: 4.15 | V19: 4.8 | W19: 4.8 | X19: 4.75 | Y19: 1.0416667 | AB19: 0 | AC19: 0 | AD19: 3 | AE19: TRUE | AF19: COMPLETE | AG19: UNSTABLE_SMALL_SAMPLE
A20: DEMO | B20: simulated-faas-burst-burst-mixed-r04 | C20: faas | D20: burst | E20: burst | F20: read | G20: 4 | H20: 574 | I20: 569 | J20: 5 | K20: 0 | L20: 47.26039 | M20: 41.358389 | N20: 85.990763 | O20: 105.10479 | P20: 13.85325 | Q20: 924.16184 | R20: 41.383823 | S20: 0.87565553 | T20: 20 | U20: 29.05 | V20: 28.7 | W20: 28.7 | X20: 28.45 | Y20: 0.87108014 | AB20: 0 | AC20: 0 | AD20: 21 | AE20: TRUE | AF20: COMPLETE | AG20: UNSTABLE_SMALL_SAMPLE
A21: DEMO | B21: simulated-faas-burst-burst-mixed-r04 | C21: faas | D21: burst | E21: burst | F21: write | G21: 4 | H21: 160 | I21: 158 | J21: 2 | K21: 0 | L21: 69.743504 | M21: 64.673646 | N21: 127.13199 | O21: 170.75816 | P21: 21.592088 | Q21: 209.39364 | R21: 32.157673 | S21: 0.46108485 | T21: 20 | U21: 8.3 | V21: 8 | W21: 8 | X21: 7.9 | Y21: 1.25 | AB21: 0 | AC21: 0 | AD21: 6 | AE21: TRUE | AF21: COMPLETE | AG21: UNSTABLE_SMALL_SAMPLE
A22: DEMO | B22: simulated-faas-burst-burst-mixed-r05 | C22: faas | D22: burst | E22: burst | F22: all | G22: 5 | H22: 830 | I22: 825 | J22: 5 | K22: 0 | L22: 76.548301 | M22: 58.504724 | N22: 176.06628 | O22: 352.70529 | P22: 13.628824 | Q22: 1141.1705 | R22: 74.935884 | S22: 0.97893596 | T22: 20 | U22: 41.5 | V22: 41.5 | W22: 41.5 | X22: 41.25 | Y22: 0.60240964 | Z22: 0 | AA22: 0 | AB22: 0 | AC22: 0 | AD22: 49 | AE22: TRUE | AF22: COMPLETE | AG22: UNSTABLE_SMALL_SAMPLE
A23: DEMO | B23: simulated-faas-burst-burst-mixed-r05 | C23: faas | D23: burst | E23: burst | F23: cpu | G23: 5 | H23: 78 | I23: 77 | J23: 1 | K23: 0 | L23: 192.67877 | M23: 171.37764 | N23: 363.30294 | O23: 395.94203 | P23: 75.534784 | Q23: 406.81314 | R23: 86.080828 | S23: 0.44675824 | T23: 20 | U23: 4.15 | V23: 3.9 | W23: 3.9 | X23: 3.85 | Y23: 1.2820513 | AB23: 0 | AC23: 0 | AD23: 4 | AE23: TRUE | AF23: COMPLETE | AG23: UNSTABLE_SMALL_SAMPLE
A24: DEMO | B24: simulated-faas-burst-burst-mixed-r05 | C24: faas | D24: burst | E24: burst | F24: read | G24: 5 | H24: 597 | I24: 594 | J24: 3 | K24: 0 | L24: 57.953907 | M24: 50.90026 | N24: 101.93026 | O24: 140.59786 | P24: 13.628824 | Q24: 855.4549 | R24: 50.625464 | S24: 0.87354705 | T24: 20 | U24: 29.05 | V24: 29.85 | W24: 29.85 | X24: 29.7 | Y24: 0.50251256 | AB24: 0 | AC24: 0 | AD24: 35 | AE24: TRUE | AF24: COMPLETE | AG24: UNSTABLE_SMALL_SAMPLE
A25: DEMO | B25: simulated-faas-burst-burst-mixed-r05 | C25: faas | D25: burst | E25: burst | F25: write | G25: 5 | H25: 155 | I25: 154 | J25: 1 | K25: 0 | L25: 89.726859 | M25: 76.903307 | N25: 141.08289 | O25: 201.2552 | P25: 27.288487 | Q25: 1141.1705 | R25: 90.876623 | S25: 1.012814 | T25: 20 | U25: 8.3 | V25: 7.75 | W25: 7.75 | X25: 7.7 | Y25: 0.64516129 | AB25: 0 | AC25: 0 | AD25: 10 | AE25: TRUE | AF25: COMPLETE | AG25: UNSTABLE_SMALL_SAMPLE
A26: DEMO | B26: simulated-faas-idle-idle-mixed-r01 | C26: faas | D26: idle | E26: idle | F26: all | G26: 1 | H26: 21 | I26: 19 | J26: 2 | K26: 0 | L26: 95.599179 | M26: 57.176987 | N26: 165.63792 | O26: 574.83334 | P26: 23.926021 | Q26: 677.1322 | R26: 138.14623 | S26: 1.4450567 | T26: 20.096171 | V26: 1.0449752 | W26: 1.0449752 | X26: 0.94545374 | Y26: 9.5238095 | Z26: 0 | AA26: 0 | AB26: 1 | AC26: 4.7619048 | AD26: 2 | AE26: FALSE | AF26: COMPLETE | AG26: UNSTABLE_SMALL_SAMPLE | AH26: INSUFFICIENT_SAMPLES
A27: DEMO | B27: simulated-faas-idle-idle-mixed-r01 | C27: faas | D27: idle | E27: idle | F27: cpu | G27: 1 | H27: 4 | I27: 3 | J27: 1 | K27: 0 | L27: 124.81198 | M27: 117.12162 | N27: 159.11345 | O27: 164.33302 | P27: 99.366742 | Q27: 165.63792 | R27: 28.768608 | S27: 0.23049557 | T27: 20.096171 | V27: 0.19904289 | W27: 0.19904289 | X27: 0.14928217 | Y27: 25 | AB27: 0 | AC27: 0 | AD27: 0 | AE27: FALSE | AF27: COMPLETE | AG27: UNSTABLE_SMALL_SAMPLE | AH27: INSUFFICIENT_SAMPLES
A28: DEMO | B28: simulated-faas-idle-idle-mixed-r01 | C28: faas | D28: idle | E28: idle | F28: read | G28: 1 | H28: 15 | I28: 15 | J28: 0 | K28: 0 | L28: 90.098282 | M28: 49.992209 | N28: 269.05957 | O28: 595.51767 | P28: 23.926021 | Q28: 677.1322 | R28: 163.41104 | S28: 1.8136976 | T28: 20.096171 | V28: 0.74641085 | W28: 0.74641085 | X28: 0.74641085 | Y28: 0 | AB28: 1 | AC28: 6.6666667 | AD28: 2 | AE28: FALSE | AF28: COMPLETE | AG28: UNSTABLE_SMALL_SAMPLE | AH28: INSUFFICIENT_SAMPLES
A29: DEMO | B29: simulated-faas-idle-idle-mixed-r01 | C29: faas | D29: idle | E29: idle | F29: write | G29: 1 | H29: 2 | I29: 1 | J29: 1 | K29: 0 | L29: 78.430307 | M29: 78.430307 | N29: 97.558296 | O29: 99.258561 | P29: 57.176987 | Q29: 99.683628 | R29: 30.056734 | S29: 0.38322856 | T29: 20.096171 | V29: 0.099521446 | W29: 0.099521446 | X29: 0.049760723 | Y29: 50 | AB29: 0 | AC29: 0 | AD29: 0 | AE29: FALSE | AF29: COMPLETE | AG29: UNSTABLE_SMALL_SAMPLE | AH29: INSUFFICIENT_SAMPLES
A30: DEMO | B30: simulated-faas-idle-idle-mixed-r02 | C30: faas | D30: idle | E30: idle | F30: all | G30: 2 | H30: 21 | I30: 21 | J30: 0 | K30: 0 | L30: 43.111234 | M30: 35.311552 | N30: 86.840598 | O30: 122.09891 | P30: 15.159653 | Q30: 130.91349 | R30: 26.318091 | S30: 0.61046944 | T30: 20.031224 | V30: 1.0483633 | W30: 1.0483633 | X30: 1.0483633 | Y30: 0 | Z30: 0 | AA30: 0 | AB30: 0 | AC30: 0 | AD30: 2 | AE30: FALSE | AF30: COMPLETE | AG30: UNSTABLE_SMALL_SAMPLE | AH30: INSUFFICIENT_SAMPLES
A31: DEMO | B31: simulated-faas-idle-idle-mixed-r02 | C31: faas | D31: idle | E31: idle | F31: cpu | G31: 2 | H31: 1 | I31: 1 | J31: 0 | K31: 0 | L31: 130.91349 | M31: 130.91349 | N31: 130.91349 | O31: 130.91349 | P31: 130.91349 | Q31: 130.91349 | T31: 20.031224 | V31: 0.049922062 | W31: 0.049922062 | X31: 0.049922062 | Y31: 0 | AB31: 0 | AC31: 0 | AD31: 0 | AE31: FALSE | AF31: COMPLETE | AG31: UNSTABLE_SMALL_SAMPLE | AH31: INSUFFICIENT_SAMPLES
A32: DEMO | B32: simulated-faas-idle-idle-mixed-r02 | C32: faas | D32: idle | E32: idle | F32: read | G32: 2 | H32: 18 | I32: 18 | J32: 0 | K32: 0 | L32: 35.367835 | M32: 33.455961 | N32: 64.05436 | O32: 65.405857 | P32: 15.159653 | Q32: 65.743731 | R32: 13.482986 | S32: 0.38122169 | T32: 20.031224 | V32: 0.89859711 | W32: 0.89859711 | X32: 0.89859711 | Y32: 0 | AB32: 0 | AC32: 0 | AD32: 1 | AE32: FALSE | AF32: COMPLETE | AG32: UNSTABLE_SMALL_SAMPLE | AH32: INSUFFICIENT_SAMPLES
A33: DEMO | B33: simulated-faas-idle-idle-mixed-r02 | C33: faas | D33: idle | E33: idle | F33: write | G33: 2 | H33: 2 | I33: 2 | J33: 0 | K33: 0 | L33: 68.900707 | M33: 68.900707 | N33: 85.046608 | O33: 86.4818 | P33: 50.960816 | Q33: 86.840598 | R33: 25.370837 | S33: 0.36822317 | T33: 20.031224 | V33: 0.099844123 | W33: 0.099844123 | X33: 0.099844123 | Y33: 0 | AB33: 0 | AC33: 0 | AD33: 1 | AE33: FALSE | AF33: COMPLETE | AG33: UNSTABLE_SMALL_SAMPLE | AH33: INSUFFICIENT_SAMPLES
A34: DEMO | B34: simulated-faas-idle-idle-mixed-r03 | C34: faas | D34: idle | E34: idle | F34: all | G34: 3 | H34: 21 | I34: 21 | J34: 0 | K34: 0 | L34: 60.670765 | M34: 34.62641 | N34: 142.21459 | O34: 321.20866 | P34: 11.780605 | Q34: 365.95718 | R34: 77.244683 | S34: 1.273178 | T34: 20.013781 | V34: 1.049277 | W34: 1.049277 | X34: 1.049277 | Y34: 0 | Z34: 0 | AA34: 0 | AB34: 1 | AC34: 4.7619048 | AD34: 1 | AE34: FALSE | AF34: COMPLETE | AG34: UNSTABLE_SMALL_SAMPLE | AH34: INSUFFICIENT_SAMPLES
A35: DEMO | B35: simulated-faas-idle-idle-mixed-r03 | C35: faas | D35: idle | E35: idle | F35: cpu | G35: 3 | H35: 2 | I35: 2 | J35: 0 | K35: 0 | L35: 136.36203 | M35: 136.36203 | N35: 141.62934 | O35: 142.09754 | P35: 130.50948 | Q35: 142.21459 | R35: 8.2767664 | S35: 0.060697 | T35: 20.013781 | V35: 0.099931142 | W35: 0.099931142 | X35: 0.099931142 | Y35: 0 | AB35: 0 | AC35: 0 | AD35: 0 | AE35: FALSE | AF35: COMPLETE | AG35: UNSTABLE_SMALL_SAMPLE | AH35: INSUFFICIENT_SAMPLES
A36: DEMO | B36: simulated-faas-idle-idle-mixed-r03 | C36: faas | D36: idle | E36: idle | F36: read | G36: 3 | H36: 15 | I36: 15 | J36: 0 | K36: 0 | L36: 54.286896 | M36: 34.442245 | N36: 143.18805 | O36: 321.40336 | P36: 11.780605 | Q36: 365.95718 | R36: 86.688473 | S36: 1.5968582 | T36: 20.013781 | V36: 0.74948357 | W36: 0.74948357 | X36: 0.74948357 | Y36: 0 | AB36: 1 | AC36: 6.6666667 | AD36: 1 | AE36: FALSE | AF36: COMPLETE | AG36: UNSTABLE_SMALL_SAMPLE | AH36: INSUFFICIENT_SAMPLES
A37: DEMO | B37: simulated-faas-idle-idle-mixed-r03 | C37: faas | D37: idle | E37: idle | F37: write | G37: 3 | H37: 4 | I37: 4 | J37: 0 | K37: 0 | L37: 46.764637 | M37: 45.985442 | N37: 66.592035 | O37: 67.514531 | P37: 27.342508 | Q37: 67.745155 | R37: 20.121893 | S37: 0.43028011 | T37: 20.013781 | V37: 0.19986228 | W37: 0.19986228 | X37: 0.19986228 | Y37: 0 | AB37: 0 | AC37: 0 | AD37: 0 | AE37: FALSE | AF37: COMPLETE | AG37: UNSTABLE_SMALL_SAMPLE | AH37: INSUFFICIENT_SAMPLES
A38: DEMO | B38: simulated-faas-idle-idle-mixed-r04 | C38: faas | D38: idle | E38: idle | F38: all | G38: 4 | H38: 21 | I38: 20 | J38: 1 | K38: 0 | L38: 83.215248 | M38: 43.411608 | N38: 110.98254 | O38: 603.66466 | P38: 20.464774 | Q38: 726.83519 | R38: 149.14867 | S38: 1.7923238 | T38: 20.035016 | V38: 1.0481649 | W38: 1.0481649 | X38: 0.99825226 | Y38: 4.7619048 | Z38: 0 | AA38: 0 | AB38: 1 | AC38: 4.7619048 | AD38: 2 | AE38: FALSE | AF38: COMPLETE | AG38: UNSTABLE_SMALL_SAMPLE | AH38: INSUFFICIENT_SAMPLES
A39: DEMO | B39: simulated-faas-idle-idle-mixed-r04 | C39: faas | D39: idle | E39: idle | F39: cpu | G39: 4 | H39: 1 | I39: 1 | J39: 0 | K39: 0 | L39: 63.839827 | M39: 63.839827 | N39: 63.839827 | O39: 63.839827 | P39: 63.839827 | Q39: 63.839827 | T39: 20.035016 | V39: 0.049912613 | W39: 0.049912613 | X39: 0.049912613 | Y39: 0 | AB39: 0 | AC39: 0 | AD39: 0 | AE39: FALSE | AF39: COMPLETE | AG39: UNSTABLE_SMALL_SAMPLE | AH39: INSUFFICIENT_SAMPLES
A40: DEMO | B40: simulated-faas-idle-idle-mixed-r04 | C40: faas | D40: idle | E40: idle | F40: read | G40: 4 | H40: 14 | I40: 14 | J40: 0 | K40: 0 | L40: 94.288555 | M40: 40.09362 | N40: 326.53096 | O40: 646.77435 | P40: 20.464774 | Q40: 726.83519 | R40: 183.36743 | S40: 1.9447474 | T40: 20.035016 | V40: 0.69877658 | W40: 0.69877658 | X40: 0.69877658 | Y40: 0 | AB40: 1 | AC40: 7.1428571 | AD40: 1 | AE40: FALSE | AF40: COMPLETE | AG40: UNSTABLE_SMALL_SAMPLE | AH40: INSUFFICIENT_SAMPLES
A41: DEMO | B41: simulated-faas-idle-idle-mixed-r04 | C41: faas | D41: idle | E41: idle | F41: write | G41: 4 | H41: 6 | I41: 5 | J41: 1 | K41: 0 | L41: 60.606767 | M41: 57.858432 | N41: 89.791863 | O41: 92.33975 | P41: 33.01618 | Q41: 92.976722 | R41: 22.980883 | S41: 0.37918015 | T41: 20.035016 | V41: 0.29947568 | W41: 0.29947568 | X41: 0.24956306 | Y41: 16.666667 | AB41: 0 | AC41: 0 | AD41: 1 | AE41: FALSE | AF41: COMPLETE | AG41: UNSTABLE_SMALL_SAMPLE | AH41: INSUFFICIENT_SAMPLES
...

Sheet Confidence
A1: Confidence
A2: SIMULATED DATA – NOT REAL CLOUD MEASUREMENTS
A3: results\processed\demo\comparison.csv
A5: data_mode | B5: model | C5: scenario | D5: load_level | E5: endpoint | F5: metric | G5: estimate | H5: ci_lower | I5: ci_upper | J5: number_of_runs | K5: bootstrap_method | L5: resamples | M5: status | N5: sample_size | O5: estimand
A6: DEMO | B6: faas | C6: burst | D6: burst | E6: all | F6: p50_ms | G6: 55.047129 | H6: 50.44825 | I6: 59.646008 | J6: 5 | K6: percentile_bootstrap_of_independent_run_means | L6: 2000 | M6: OK | N6: 4150 | O6: mean_of_run_statistics
A7: DEMO | B7: faas | C7: burst | D7: burst | E7: all | F7: p95_ms | G7: 161.32093 | H7: 146.82798 | I7: 173.80086 | J7: 5 | K7: percentile_bootstrap_of_independent_run_means | L7: 2000 | M7: OK | N7: 4150 | O7: mean_of_run_statistics
A8: DEMO | B8: faas | C8: burst | D8: burst | E8: all | F8: p99_ms | G8: 282.8606 | H8: 250.55925 | I8: 323.85079 | J8: 5 | K8: percentile_bootstrap_of_independent_run_means | L8: 2000 | M8: OK | N8: 4150 | O8: mean_of_run_statistics
A9: DEMO | B9: faas | C9: burst | D9: burst | E9: all | F9: mean_ms | G9: 70.972942 | H9: 65.130258 | I9: 76.388415 | J9: 5 | K9: percentile_bootstrap_of_independent_run_means | L9: 2000 | M9: OK | N9: 4150 | O9: mean_of_run_statistics
A10: DEMO | B10: faas | C10: burst | D10: burst | E10: all | F10: achieved_rps | G10: 41.5 | H10: 41.5 | I10: 41.5 | J10: 5 | K10: percentile_bootstrap_of_independent_run_means | L10: 2000 | M10: OK | N10: 4150 | O10: mean_of_run_statistics
A11: DEMO | B11: faas | C11: burst | D11: burst | E11: all | F11: error_rate_pct | G11: 1.253012 | H11: 0.89156627 | I11: 1.6144578 | J11: 5 | K11: percentile_bootstrap_of_independent_run_means | L11: 2000 | M11: OK | N11: 4150 | O11: mean_of_run_statistics
A12: DEMO | B12: faas | C12: burst | D12: burst | E12: cpu | F12: p50_ms | G12: 148.6695 | H12: 135.37977 | I12: 162.46404 | J12: 5 | K12: percentile_bootstrap_of_independent_run_means | L12: 2000 | M12: OK | N12: 431 | O12: mean_of_run_statistics
A13: DEMO | B13: faas | C13: burst | D13: burst | E13: cpu | F13: p95_ms | G13: 289.71742 | H13: 265.40264 | I13: 326.64158 | J13: 5 | K13: percentile_bootstrap_of_independent_run_means | L13: 2000 | M13: OK | N13: 431 | O13: mean_of_run_statistics
A14: DEMO | B14: faas | C14: burst | D14: burst | E14: cpu | F14: p99_ms | G14: 428.63567 | H14: 365.39887 | I14: 514.04611 | J14: 5 | K14: percentile_bootstrap_of_independent_run_means | L14: 2000 | M14: OK | N14: 431 | O14: mean_of_run_statistics
A15: DEMO | B15: faas | C15: burst | D15: burst | E15: cpu | F15: mean_ms | G15: 167.33933 | H15: 153.49555 | I15: 183.16747 | J15: 5 | K15: percentile_bootstrap_of_independent_run_means | L15: 2000 | M15: OK | N15: 431 | O15: mean_of_run_statistics
A16: DEMO | B16: faas | C16: burst | D16: burst | E16: cpu | F16: achieved_rps | G16: 4.31 | H16: 4.06 | I16: 4.61 | J16: 5 | K16: percentile_bootstrap_of_independent_run_means | L16: 2000 | M16: OK | N16: 431 | O16: mean_of_run_statistics
A17: DEMO | B17: faas | C17: burst | D17: burst | E17: cpu | F17: error_rate_pct | G17: 1.3882471 | H17: 1.1195055 | I17: 1.8123924 | J17: 5 | K17: percentile_bootstrap_of_independent_run_means | L17: 2000 | M17: OK | N17: 431 | O17: mean_of_run_statistics
... A257: DEMO | B257: paas | C257: steady | D257: medium | E257: write | F257: error_rate_pct | G257: 0.46785226 | H257: 0 | I257: 0.93844049 | J257: 5 | K257: percentile_bootstrap_of_independent_run_means | L257: 2000 | M257: OK | N257: 358 | O257: mean_of_run_statistics

Sheet Cold Warm
A1: Cold Warm
A2: SIMULATED DATA – NOT REAL CLOUD MEASUREMENTS
A3: results\processed\demo\cold_warm.csv
A5: data_mode | B5: model | C5: scenario | D5: endpoint | E5: run_id | F5: classification | G5: request_count | H5: mean_ms | I5: p50_ms | J5: p95_ms | K5: p99_ms | L5: min_ms | M5: max_ms | N5: std_ms | O5: cv | P5: tail_warning | Q5: handler_mean_ms | R5: wall_mean_ms
A6: DEMO | B6: faas | C6: burst | D6: cpu | E6: simulated-faas-burst-burst-mixed-r01 | F6: confirmed_warm | G6: 80 | H6: 179.20325 | I6: 157.18941 | J6: 263.03475 | L6: 51.196236 | M6: 1488.7454 | N6: 160.34404 | O6: 0.89476077 | P6: p95 requires >=20, p99 requires >=1000 samples; no guarantees at these minimums | Q6: 129.50893 | R6: 181.20325
A7: DEMO | B7: faas | C7: burst | D7: cpu | E7: simulated-faas-burst-burst-mixed-r01 | F7: unknown | G7: 3 | H7: 213.85998 | I7: 250.66636 | L7: 130.98003 | M7: 259.93355 | N7: 71.925553 | O7: 0.33632077 | P7: p95 requires >=20, p99 requires >=1000 samples; no guarantees at these minimums | Q7: 153.97919 | R7: 215.85998
A8: DEMO | B8: faas | C8: burst | D8: cpu | E8: simulated-faas-burst-burst-mixed-r02 | F8: confirmed_warm | G8: 76 | H8: 147.56879 | I8: 127.01131 | J8: 275.71106 | L8: 56.410148 | M8: 505.28224 | N8: 75.459177 | O8: 0.51134915 | P8: p95 requires >=20, p99 requires >=1000 samples; no guarantees at these minimums | Q8: 107.58341 | R8: 149.56879
A9: DEMO | B9: faas | C9: burst | D9: cpu | E9: simulated-faas-burst-burst-mixed-r02 | F9: unknown | G9: 8 | H9: 137.08786 | I9: 120.55144 | L9: 68.178765 | M9: 283.95139 | N9: 69.074251 | O9: 0.50386848 | P9: p95 requires >=20, p99 requires >=1000 samples; no guarantees at these minimums | Q9: 101.76871 | R9: 139.08786
A10: DEMO | B10: faas | C10: burst | D10: cpu | E10: simulated-faas-burst-burst-mixed-r03 | F10: confirmed_warm | G10: 84 | H10: 161.34814 | I10: 153.21861 | J10: 281.01646 | L10: 61.672689 | M10: 356.13958 | N10: 61.727325 | O10: 0.38257227 | P10: p95 requires >=20, p99 requires >=1000 samples; no guarantees at these minimums | Q10: 116.77345 | R10: 163.34814
A11: DEMO | B11: faas | C11: burst | D11: cpu | E11: simulated-faas-burst-burst-mixed-r03 | F11: unknown | G11: 6 | H11: 101.30307 | I11: 98.612915 | L11: 75.682048 | M11: 130.10219 | N11: 20.978714 | O11: 0.20708863 | P11: p95 requires >=20, p99 requires >=1000 samples; no guarantees at these minimums | Q11: 72.938213 | R11: 103.30307
A12: DEMO | B12: faas | C12: burst | D12: cpu | E12: simulated-faas-burst-burst-mixed-r04 | F12: confirmed_warm | G12: 93 | H12: 158.89584 | I12: 133.77664 | J12: 264.03801 | L12: 49.701554 | M12: 1702.56 | N12: 173.77481 | O12: 1.0936398 | P12: p95 requires >=20, p99 requires >=1000 samples; no guarantees at these minimums | Q12: 114.51612 | R12: 160.89584
A13: DEMO | B13: faas | C13: burst | D13: cpu | E13: simulated-faas-burst-burst-mixed-r04 | F13: unknown | G13: 3 | H13: 182.90836 | I13: 189.74337 | L13: 165.92172 | M13: 193.06 | N13: 14.804041 | O13: 0.080936926 | P13: p95 requires >=20, p99 requires >=1000 samples; no guarantees at these minimums | Q13: 128.03943 | R13: 184.90836
A14: DEMO | B14: faas | C14: burst | D14: cpu | E14: simulated-faas-burst-burst-mixed-r05 | F14: confirmed_warm | G14: 74 | H14: 195.20664 | I14: 171.37764 | J14: 363.33099 | L14: 75.534784 | M14: 406.81314 | N14: 86.949551 | O14: 0.44542313 | P14: p95 requires >=20, p99 requires >=1000 samples; no guarantees at these minimums | Q14: 139.98207 | R14: 197.20664
A15: DEMO | B15: faas | C15: burst | D15: cpu | E15: simulated-faas-burst-burst-mixed-r05 | F15: unknown | G15: 4 | H15: 145.91321 | I15: 147.22356 | L15: 87.980056 | M15: 201.22567 | N15: 56.111976 | O15: 0.3845572 | P15: p95 requires >=20, p99 requires >=1000 samples; no guarantees at these minimums | Q15: 105.05751 | R15: 147.91321
A16: DEMO | B16: faas | C16: burst | D16: read | E16: simulated-faas-burst-burst-mixed-r01 | F16: confirmed_warm | G16: 552 | H16: 57.933708 | I16: 53.331765 | J16: 101.54906 | L16: 15.696553 | M16: 498.52723 | N16: 29.31717 | O16: 0.50604684 | P16: p95 requires >=20, p99 requires >=1000 samples; no guarantees at these minimums | Q16: 41.654953 | R16: 59.933708
A17: DEMO | B17: faas | C17: burst | D17: read | E17: simulated-faas-burst-burst-mixed-r01 | F17: unknown | G17: 34 | H17: 59.224866 | I17: 56.360722 | J17: 107.91133 | L17: 21.197203 | M17: 111.04001 | N17: 24.830066 | O17: 0.41925069 | P17: p95 requires >=20, p99 requires >=1000 samples; no guarantees at these minimums | Q17: 42.300026 | R17: 61.224866
A18: DEMO | B18: faas | C18: burst | D18: read | E18: simulated-faas-burst-burst-mixed-r02 | F18: confirmed_warm | G18: 546 | H18: 46.400448 | I18: 41.143275 | J18: 77.735063 | L18: 11.806276 | M18: 587.50153 | N18: 29.708113 | O18: 0.64025486 | P18: p95 requires >=20, p99 requires >=1000 samples; no guarantees at these minimums | Q18: 33.403873 | R18: 48.400448
A19: DEMO | B19: faas | C19: burst | D19: read | E19: simulated-faas-burst-burst-mixed-r02 | F19: unknown | G19: 29 | H19: 63.45348 | I19: 40.811035 | J19: 112.56101 | L19: 17.200611 | M19: 535.71532 | N19: 93.663222 | O19: 1.4760928 | P19: p95 requires >=20, p99 requires >=1000 samples; no guarantees at these minimums | Q19: 45.686506 | R19: 65.45348
A20: DEMO | B20: faas | C20: burst | D20: read | E20: simulated-faas-burst-burst-mixed-r03 | F20: confirmed_warm | G20: 531 | H20: 62.476217 | I20: 50.167961 | J20: 104.37441 | L20: 13.574096 | M20: 932.97067 | N20: 75.744991 | O20: 1.2123812 | P20: p95 requires >=20, p99 requires >=1000 samples; no guarantees at these minimums | Q20: 45.390511 | R20: 64.476217
A21: DEMO | B21: faas | C21: burst | D21: read | E21: simulated-faas-burst-burst-mixed-r03 | F21: unknown | G21: 37 | H21: 51.611368 | I21: 46.410552 | J21: 85.679094 | L21: 22.762219 | M21: 134.6303 | N21: 21.693547 | O21: 0.42032498 | P21: p95 requires >=20, p99 requires >=1000 samples; no guarantees at these minimums | Q21: 37.530704 | R21: 53.611368
A22: DEMO | B22: faas | C22: burst | D22: read | E22: simulated-faas-burst-burst-mixed-r04 | F22: confirmed_warm | G22: 553 | H22: 47.202117 | I22: 40.97066 | J22: 85.37645 | L22: 13.85325 | M22: 924.16184 | N22: 41.926261 | O22: 0.8882284 | P22: p95 requires >=20, p99 requires >=1000 samples; no guarantees at these minimums | Q22: 33.962372 | R22: 49.202117
A23: DEMO | B23: faas | C23: burst | D23: read | E23: simulated-faas-burst-burst-mixed-r04 | F23: unknown | G23: 21 | H23: 48.794931 | I23: 45.717809 | J23: 86.322221 | L23: 16.035421 | M23: 96.324255 | N23: 23.418495 | O23: 0.47993704 | P23: p95 requires >=20, p99 requires >=1000 samples; no guarantees at these minimums | Q23: 35.132351 | R23: 50.794931
A24: DEMO | B24: faas | C24: burst | D24: read | E24: simulated-faas-burst-burst-mixed-r05 | F24: confirmed_warm | G24: 562 | H24: 57.958821 | I24: 50.908113 | J24: 101.37136 | L24: 13.628824 | M24: 855.4549 | N24: 51.833973 | O24: 0.89432415 | P24: p95 requires >=20, p99 requires >=1000 samples; no guarantees at these minimums | Q24: 39.899784 | R24: 59.958821
A25: DEMO | B25: faas | C25: burst | D25: read | E25: simulated-faas-burst-burst-mixed-r05 | F25: unknown | G25: 35 | H25: 57.874998 | I25: 50.403011 | J25: 111.18852 | L25: 26.060418 | M25: 113.45339 | N25: 24.397321 | O25: 0.42155199 | P25: p95 requires >=20, p99 requires >=1000 samples; no guarantees at these minimums | Q25: 42.95909 | R25: 59.874998
A26: DEMO | B26: faas | C26: burst | D26: write | E26: simulated-faas-burst-burst-mixed-r01 | F26: confirmed_warm | G26: 155 | H26: 85.427204 | I26: 78.247321 | J26: 163.54148 | L26: 25.392753 | M26: 241.75394 | N26: 38.312485 | O26: 0.44848109 | P26: p95 requires >=20, p99 requires >=1000 samples; no guarantees at these minimums | Q26: 61.392318 | R26: 87.427204
A27: DEMO | B27: faas | C27: burst | D27: write | E27: simulated-faas-burst-burst-mixed-r01 | F27: unknown | G27: 6 | H27: 88.519034 | I27: 101.3725 | L27: 29.250192 | M27: 129.55194 | N27: 40.546613 | O27: 0.4580553 | P27: p95 requires >=20, p99 requires >=1000 samples; no guarantees at these minimums | Q27: 63.733705 | R27: 90.519034
A28: DEMO | B28: faas | C28: burst | D28: write | E28: simulated-faas-burst-burst-mixed-r02 | F28: confirmed_warm | G28: 167 | H28: 67.457928 | I28: 61.843339 | J28: 125.90636 | L28: 21.749134 | M28: 182.91678 | N28: 29.212585 | O28: 0.43304895 | P28: p95 requires >=20, p99 requires >=1000 samples; no guarantees at these minimums | Q28: 48.241238 | R28: 69.457928
A29: DEMO | B29: faas | C29: burst | D29: write | E29: simulated-faas-burst-burst-mixed-r02 | F29: unknown | G29: 4 | H29: 73.868162 | I29: 66.638213 | L29: 48.397915 | M29: 113.79831 | N29: 30.679662 | O29: 0.41532997 | P29: p95 requires >=20, p99 requires >=1000 samples; no guarantees at these minimums | Q29: 53.185077 | R29: 75.868162
A30: DEMO | B30: faas | C30: burst | D30: write | E30: simulated-faas-burst-burst-mixed-r03 | F30: confirmed_warm | G30: 158 | H30: 83.391387 | I30: 77.404886 | J30: 143.95315 | L30: 21.631114 | M30: 221.40202 | N30: 34.051726 | O30: 0.40833624 | P30: p95 requires >=20, p99 requires >=1000 samples; no guarantees at these minimums | Q30: 60.349672 | R30: 85.391387
A31: DEMO | B31: faas | C31: burst | D31: write | E31: simulated-faas-burst-burst-mixed-r03 | F31: unknown | G31: 14 | H31: 84.133265 | I31: 72.210513 | L31: 31.341319 | M31: 137.67265 | N31: 31.738466 | O31: 0.37724039 | P31: p95 requires >=20, p99 requires >=1000 samples; no guarantees at these minimums | Q31: 59.853992 | R31: 86.133265
A32: DEMO | B32: faas | C32: burst | D32: write | E32: simulated-faas-burst-burst-mixed-r04 | F32: confirmed_warm | G32: 154 | H32: 69.306068 | I32: 64.439192 | J32: 126.45909 | L32: 21.592088 | M32: 209.39364 | N32: 31.865827 | O32: 0.45978409 | P32: p95 requires >=20, p99 requires >=1000 samples; no guarantees at these minimums | Q32: 49.193691 | R32: 71.306068
A33: DEMO | B33: faas | C33: burst | D33: write | E33: simulated-faas-burst-burst-mixed-r04 | F33: unknown | G33: 6 | H33: 80.971031 | I33: 80.889905 | L33: 27.082159 | M33: 133.7492 | N33: 40.688289 | O33: 0.50250427 | P33: p95 requires >=20, p99 requires >=1000 samples; no guarantees at these minimums | Q33: 58.299142 | R33: 82.971031
A34: DEMO | B34: faas | C34: burst | D34: write | E34: simulated-faas-burst-burst-mixed-r05 | F34: confirmed_warm | G34: 145 | H34: 88.515936 | I34: 74.166554 | J34: 138.51434 | L34: 27.288487 | M34: 1141.1705 | N34: 93.569205 | O34: 1.0570888 | P34: p95 requires >=20, p99 requires >=1000 samples; no guarantees at these minimums | Q34: 64.357033 | R34: 90.515936
A35: DEMO | B35: faas | C35: burst | D35: write | E35: simulated-faas-burst-burst-mixed-r05 | F35: unknown | G35: 10 | H35: 107.28525 | I35: 103.16997 | L35: 75.415948 | M35: 167.84364 | N35: 29.391049 | O35: 0.27395239 | P35: p95 requires >=20, p99 requires >=1000 samples; no guarantees at these minimums | Q35: 77.245377 | R35: 109.28525
A36: DEMO | B36: faas | C36: idle | D36: cpu | E36: simulated-faas-idle-idle-mixed-r01 | F36: confirmed_warm | G36: 4 | H36: 124.81198 | I36: 117.12162 | L36: 99.366742 | M36: 165.63792 | N36: 28.768608 | O36: 0.23049557 | P36: p95 requires >=20, p99 requires >=1000 samples; no guarantees at these minimums | Q36: 89.864622 | R36: 126.81198
A37: DEMO | B37: faas | C37: idle | D37: cpu | E37: simulated-faas-idle-idle-mixed-r02 | F37: confirmed_warm | G37: 1 | H37: 130.91349 | I37: 130.91349 | L37: 130.91349 | M37: 130.91349 | P37: p95 requires >=20, p99 requires >=1000 samples; no guarantees at these minimums | Q37: 94.25771 | R37: 132.91349
A38: DEMO | B38: faas | C38: idle | D38: cpu | E38: simulated-faas-idle-idle-mixed-r03 | F38: confirmed_warm | G38: 2 | H38: 136.36203 | I38: 136.36203 | L38: 130.50948 | M38: 142.21459 | N38: 8.2767664 | O38: 0.060697 | P38: p95 requires >=20, p99 requires >=1000 samples; no guarantees at these minimums | Q38: 98.180665 | R38: 138.36203
A39: DEMO | B39: faas | C39: idle | D39: cpu | E39: simulated-faas-idle-idle-mixed-r04 | F39: confirmed_warm | G39: 1 | H39: 63.839827 | I39: 63.839827 | L39: 63.839827 | M39: 63.839827 | P39: p95 requires >=20, p99 requires >=1000 samples; no guarantees at these minimums | Q39: 45.964675 | R39: 65.839827
A40: DEMO | B40: faas | C40: idle | D40: cpu | E40: simulated-faas-idle-idle-mixed-r05 | F40: confirmed_warm | G40: 2 | H40: 92.196162 | I40: 92.196162 | L40: 79.694749 | M40: 104.69758 | N40: 17.679668 | O40: 0.19176143 | P40: p95 requires >=20, p99 requires >=1000 samples; no guarantees at these minimums | Q40: 66.381237 | R40: 94.196162
A41: DEMO | B41: faas | C41: idle | D41: read | E41: simulated-faas-idle-idle-mixed-r01 | F41: confirmed_cold | G41: 1 | H41: 677.1322 | I41: 677.1322 | L41: 677.1322 | M41: 677.1322 | P41: p95 requires >=20, p99 requires >=1000 samples; no guarantees at these minimums | Q41: 487.53518 | R41: 679.1322
...

Sheet Scaling
A1: Scaling
A2: SIMULATED DATA – NOT REAL CLOUD MEASUREMENTS
A3: results\processed\demo\scaling.csv
A5: data_mode | B5: run_id | C5: model | D5: scenario | E5: status | F5: scale_out_seconds | G5: scale_out_lower_seconds | H5: scale_out_upper_seconds | I5: baseline_instances | J5: peak_instances | K5: recovery_seconds | L5: sampling_seconds | M5: burst_started_at | N5: observed_increase_at | O5: peak_at
A6: DEMO | B6: simulated-faas-burst-burst-mixed-r01 | C6: faas | D6: burst | E6: OBSERVED_INTERVAL | F6: 54 | G6: 0 | H6: 54 | I6: 1 | J6: 2 | K6: 106 | L6: 60 | M6: 2026-10-01T10:00:06+00:00 | N6: 2026-10-01T10:01:00+00:00 | O6: 2026-10-01T10:01:00+00:00
A7: DEMO | B7: simulated-faas-burst-burst-mixed-r02 | C7: faas | D7: burst | E7: OBSERVED_INTERVAL | F7: 54 | G7: 0 | H7: 54 | I7: 1 | J7: 2 | K7: 106 | L7: 60 | M7: 2026-10-02T01:00:06+00:00 | N7: 2026-10-02T01:01:00+00:00 | O7: 2026-10-02T01:01:00+00:00
A8: DEMO | B8: simulated-faas-burst-burst-mixed-r03 | C8: faas | D8: burst | E8: OBSERVED_INTERVAL | F8: 54 | G8: 0 | H8: 54 | I8: 1 | J8: 2 | K8: 106 | L8: 60 | M8: 2026-10-02T16:00:06+00:00 | N8: 2026-10-02T16:01:00+00:00 | O8: 2026-10-02T16:01:00+00:00
A9: DEMO | B9: simulated-faas-burst-burst-mixed-r04 | C9: faas | D9: burst | E9: OBSERVED_INTERVAL | F9: 54 | G9: 0 | H9: 54 | I9: 1 | J9: 2 | K9: 106 | L9: 60 | M9: 2026-10-03T07:00:06+00:00 | N9: 2026-10-03T07:01:00+00:00 | O9: 2026-10-03T07:01:00+00:00
A10: DEMO | B10: simulated-faas-burst-burst-mixed-r05 | C10: faas | D10: burst | E10: OBSERVED_INTERVAL | F10: 54 | G10: 0 | H10: 54 | I10: 1 | J10: 2 | K10: 106 | L10: 60 | M10: 2026-10-03T21:00:06+00:00 | N10: 2026-10-03T21:01:00+00:00 | O10: 2026-10-03T21:01:00+00:00
A11: DEMO | B11: simulated-faas-idle-idle-mixed-r01 | C11: faas | D11: idle | E11: NOT_APPLICABLE_SCENARIO
A12: DEMO | B12: simulated-faas-idle-idle-mixed-r02 | C12: faas | D12: idle | E12: NOT_APPLICABLE_SCENARIO
A13: DEMO | B13: simulated-faas-idle-idle-mixed-r03 | C13: faas | D13: idle | E13: NOT_APPLICABLE_SCENARIO
A14: DEMO | B14: simulated-faas-idle-idle-mixed-r04 | C14: faas | D14: idle | E14: NOT_APPLICABLE_SCENARIO
A15: DEMO | B15: simulated-faas-idle-idle-mixed-r05 | C15: faas | D15: idle | E15: NOT_APPLICABLE_SCENARIO
A16: DEMO | B16: simulated-faas-steady-high-mixed-r01 | C16: faas | D16: steady | E16: NOT_APPLICABLE_SCENARIO
A17: DEMO | B17: simulated-faas-steady-high-mixed-r02 | C17: faas | D17: steady | E17: NOT_APPLICABLE_SCENARIO
A18: DEMO | B18: simulated-faas-steady-high-mixed-r03 | C18: faas | D18: steady | E18: NOT_APPLICABLE_SCENARIO
A19: DEMO | B19: simulated-faas-steady-high-mixed-r04 | C19: faas | D19: steady | E19: NOT_APPLICABLE_SCENARIO
A20: DEMO | B20: simulated-faas-steady-high-mixed-r05 | C20: faas | D20: steady | E20: NOT_APPLICABLE_SCENARIO
A21: DEMO | B21: simulated-faas-steady-low-mixed-r01 | C21: faas | D21: steady | E21: NOT_APPLICABLE_SCENARIO
A22: DEMO | B22: simulated-faas-steady-low-mixed-r02 | C22: faas | D22: steady | E22: NOT_APPLICABLE_SCENARIO
... A55: DEMO | B55: simulated-iaas-steady-medium-mixed-r05 | C55: iaas | D55: steady | E55: NOT_APPLICABLE_FIXED_VM
A56: DEMO | B56: simulated-paas-burst-burst-mixed-r01 | C56: paas | D56: burst | E56: OBSERVED_INTERVAL | F56: 54 | G56: 0 | H56: 54 | I56: 1 | J56: 2 | K56: 106 | L56: 60 | M56: 2026-10-01T09:00:06+00:00 | N56: 2026-10-01T09:01:00+00:00 | O56: 2026-10-01T09:01:00+00:00
A57: DEMO | B57: simulated-paas-burst-burst-mixed-r02 | C57: paas | D57: burst | E57: OBSERVED_INTERVAL | F57: 54 | G57: 0 | H57: 54 | I57: 1 | J57: 2 | K57: 106 | L57: 60 | M57: 2026-10-02T00:00:06+00:00 | N57: 2026-10-02T00:01:00+00:00 | O57: 2026-10-02T00:01:00+00:00
A58: DEMO | B58: simulated-paas-burst-burst-mixed-r03 | C58: paas | D58: burst | E58: OBSERVED_INTERVAL | F58: 54 | G58: 0 | H58: 54 | I58: 1 | J58: 2 | K58: 106 | L58: 60 | M58: 2026-10-02T15:00:06+00:00 | N58: 2026-10-02T15:01:00+00:00 | O58: 2026-10-02T15:01:00+00:00
A59: DEMO | B59: simulated-paas-burst-burst-mixed-r04 | C59: paas | D59: burst | E59: OBSERVED_INTERVAL | F59: 54 | G59: 0 | H59: 54 | I59: 1 | J59: 2 | K59: 106 | L59: 60 | M59: 2026-10-03T08:00:06+00:00 | N59: 2026-10-03T08:01:00+00:00 | O59: 2026-10-03T08:01:00+00:00
A60: DEMO | B60: simulated-paas-burst-burst-mixed-r05 | C60: paas | D60: burst | E60: OBSERVED_INTERVAL | F60: 54 | G60: 0 | H60: 54 | I60: 1 | J60: 2 | K60: 106 | L60: 60 | M60: 2026-10-03T23:00:06+00:00 | N60: 2026-10-03T23:01:00+00:00 | O60: 2026-10-03T23:01:00+00:00
A61: DEMO | B61: simulated-paas-idle-idle-mixed-r01 | C61: paas | D61: idle | E61: NOT_APPLICABLE_SCENARIO
A62: DEMO | B62: simulated-paas-idle-idle-mixed-r02 | C62: paas | D62: idle | E62: NOT_APPLICABLE_SCENARIO
A63: DEMO | B63: simulated-paas-idle-idle-mixed-r03 | C63: paas | D63: idle | E63: NOT_APPLICABLE_SCENARIO
A64: DEMO | B64: simulated-paas-idle-idle-mixed-r04 | C64: paas | D64: idle | E64: NOT_APPLICABLE_SCENARIO
A65: DEMO | B65: simulated-paas-idle-idle-mixed-r05 | C65: paas | D65: idle | E65: NOT_APPLICABLE_SCENARIO
A66: DEMO | B66: simulated-paas-steady-high-mixed-r01 | C66: paas | D66: steady | E66: NOT_APPLICABLE_SCENARIO
A67: DEMO | B67: simulated-paas-steady-high-mixed-r02 | C67: paas | D67: steady | E67: NOT_APPLICABLE_SCENARIO
A68: DEMO | B68: simulated-paas-steady-high-mixed-r03 | C68: paas | D68: steady | E68: NOT_APPLICABLE_SCENARIO
A69: DEMO | B69: simulated-paas-steady-high-mixed-r04 | C69: paas | D69: steady | E69: NOT_APPLICABLE_SCENARIO
A70: DEMO | B70: simulated-paas-steady-high-mixed-r05 | C70: paas | D70: steady | E70: NOT_APPLICABLE_SCENARIO
A71: DEMO | B71: simulated-paas-steady-low-mixed-r01 | C71: paas | D71: steady | E71: NOT_APPLICABLE_SCENARIO
A72: DEMO | B72: simulated-paas-steady-low-mixed-r02 | C72: paas | D72: steady | E72: NOT_APPLICABLE_SCENARIO
... A80: DEMO | B80: simulated-paas-steady-medium-mixed-r05 | C80: paas | D80: steady | E80: NOT_APPLICABLE_SCENARIO

Sheet Burst Phases
A1: Burst Phases
A2: SIMULATED DATA – NOT REAL CLOUD MEASUREMENTS
A3: results\processed\demo\burst_phases.csv
A5: data_mode | B5: run_id | C5: model | D5: stage | E5: request_count | F5: p95_ms | G5: p99_ms | H5: error_rate_pct | I5: cohort_rps
A6: DEMO | B6: simulated-faas-burst-burst-mixed-r01 | C6: faas | D6: baseline | E6: 61 | F6: 138.9098 | G6: 690.82317 | H6: 1.6393443 | I6: 10.166667
A7: DEMO | B7: simulated-faas-burst-burst-mixed-r01 | C7: faas | D7: hold | E7: 600 | F7: 183.08886 | G7: 259.94562 | H7: 1.6666667 | I7: 100
A8: DEMO | B8: simulated-faas-burst-burst-mixed-r01 | C8: faas | D8: ramp_down | E8: 10 | F8: 80.056466 | G8: 80.143963 | H8: 0 | I8: 10
A9: DEMO | B9: simulated-faas-burst-burst-mixed-r01 | C9: faas | D9: ramp_up | E9: 100 | F9: 155.79112 | G9: 199.81213 | H9: 2 | I9: 100
A10: DEMO | B10: simulated-faas-burst-burst-mixed-r01 | C10: faas | D10: recovery | E10: 59 | F10: 98.856694 | G10: 160.61296 | H10: 0 | I10: 9.8333333
A11: DEMO | B11: simulated-faas-burst-burst-mixed-r02 | C11: faas | D11: baseline | E11: 61 | F11: 114.87175 | G11: 197.12421 | H11: 1.6393443 | I11: 10.166667
A12: DEMO | B12: simulated-faas-burst-burst-mixed-r02 | C12: faas | D12: hold | E12: 600 | F12: 139.93096 | G12: 250.68757 | H12: 1.5 | I12: 100
A13: DEMO | B13: simulated-faas-burst-burst-mixed-r02 | C13: faas | D13: ramp_down | E13: 10 | F13: 182.67738 | G13: 214.65808 | H13: 0 | I13: 10
A14: DEMO | B14: simulated-faas-burst-burst-mixed-r02 | C14: faas | D14: ramp_up | E14: 100 | F14: 161.07603 | G14: 506.10444 | H14: 1 | I14: 100
A15: DEMO | B15: simulated-faas-burst-burst-mixed-r02 | C15: faas | D15: recovery | E15: 59 | F15: 100.89165 | G15: 154.65078 | H15: 0 | I15: 9.8333333
A16: DEMO | B16: simulated-faas-burst-burst-mixed-r03 | C16: faas | D16: baseline | E16: 61 | F16: 124.35446 | G16: 215.41147 | H16: 1.6393443 | I16: 10.166667
A17: DEMO | B17: simulated-faas-burst-burst-mixed-r03 | C17: faas | D17: hold | E17: 600 | F17: 184.06299 | G17: 315.75734 | H17: 1.8333333 | I17: 100
... A80: DEMO | B80: simulated-paas-burst-burst-mixed-r05 | C80: paas | D80: recovery | E80: 59 | F80: 88.220857 | G80: 123.38509 | H80: 1.6949153 | I80: 9.8333333

Sheet Errors
A1: Errors
A2: SIMULATED DATA – NOT REAL CLOUD MEASUREMENTS
A3: results\processed\demo\errors.csv
A5: data_mode | B5: model | C5: scenario | D5: endpoint | E5: status | F5: error_type | G5: request_count
A6: DEMO | B6: faas | C6: burst | D6: cpu | E6: 200 | F6: business_error | G6: 1
A7: DEMO | B7: faas | C7: burst | D7: cpu | E7: 200 | F7: none | G7: 425
A8: DEMO | B8: faas | C8: burst | D8: cpu | E8: 503 | F8: http_error | G8: 5
A9: DEMO | B9: faas | C9: burst | D9: read | E9: 0 | F9: transport_or_timeout | G9: 3
A10: DEMO | B10: faas | C10: burst | D10: read | E10: 200 | F10: business_error | G10: 2
A11: DEMO | B11: faas | C11: burst | D11: read | E11: 200 | F11: none | G11: 2868
A12: DEMO | B12: faas | C12: burst | D12: read | E12: 503 | F12: http_error | G12: 27
A13: DEMO | B13: faas | C13: burst | D13: write | E13: 0 | F13: transport_or_timeout | G13: 2
A14: DEMO | B14: faas | C14: burst | D14: write | E14: 201 | F14: business_error | G14: 2
A15: DEMO | B15: faas | C15: burst | D15: write | E15: 201 | F15: none | G15: 805
A16: DEMO | B16: faas | C16: burst | D16: write | E16: 503 | F16: http_error | G16: 10
A17: DEMO | B17: faas | C17: idle | D17: cpu | E17: 200 | F17: none | G17: 9
... A87: DEMO | B87: paas | C87: steady | D87: write | E87: 503 | F87: http_error | G87: 10

Sheet Cost Breakdown
A1: Cost Breakdown
A2: SIMULATED DATA – NOT REAL CLOUD MEASUREMENTS
A3: results\financial\demo\cost_breakdown.csv
A5: level | B5: data_mode | C5: model | D5: component | E5: usd
A6: low | B6: DEMO | C6: iaas | D6: firestore_read | E6: 0.02583
A7: low | B7: DEMO | C7: iaas | D7: firestore_write | E7: 0.02214
A8: low | B8: DEMO | C8: iaas | D8: firestore_delete | E8: 0
A9: low | B9: DEMO | C9: iaas | D9: firestore_storage | E9: 0.1846
A10: low | B10: DEMO | C10: iaas | D10: firestore_network_optional | E10: 0
A11: low | B11: DEMO | C11: iaas | D11: network | E11: 0
A12: low | B12: DEMO | C12: iaas | D12: logging | E12: 0
A13: low | B13: DEMO | C13: iaas | D13: monitoring | E13: 0
A14: low | B14: DEMO | C14: iaas | D14: build | E14: 0
A15: low | B15: DEMO | C15: iaas | D15: artifact | E15: 0
A16: low | B16: DEMO | C16: iaas | D16: backup_auxiliary | E16: 0
A17: low | B17: DEMO | C17: iaas | D17: labor | E17: 0
... A140: high | B140: DEMO | C140: faas | D140: requests | E140: 8

Sheet Cost Summary
A1: Cost Summary | N1: Cost comparison | formula-linked totals
A2: SIMULATED DATA – NOT REAL CLOUD MEASUREMENTS | N2: SIMULATED DATA – NOT REAL CLOUD MEASUREMENTS
A3: results\financial\demo\cost_levels.csv; totals recalculate from Cost Breakdown | N3: Cost Summary and Cost Breakdown; USD/month estimates; capacity separately validated
A5: level | B5: model | C5: monthly_requests | D5: python_total_usd | E5: python_compute_usd | F5: python_shared_usd | G5: python_without_shared_usd | H5: python_unit_usd | I5: capacity_status | J5: calculated_total_usd | K5: difference_usd | L5: check | M5: lookup_key | N5: Model | O5: Low USD | P5: Medium USD | Q5: High USD
A6: low | B6: iaas | C6: 100000 | D6: 61.018852 | E6: 60.346282 | F6: 0.23257 | G6: 60.786282 | H6: 610.18852 | I6: UNVERIFIED | J6: =SUMIFS('Cost Breakdown'!$E$6:$E$140,'Cost Breakdown'!$A$6:$A$140,A6,'Cost Breakdown'!$C$6:$C$140,B6) -> 61.018852 | K6: =J6-D6 -> 0 | L6: =IF(ABS(K6)<0.000001,"OK","CHECK") -> OK | M6: =A6&"|"&B6 -> low|iaas | N6: IAAS | O6: =SUMIFS($J$6:$J$14,$A$6:$A$14,"low",$B$6:$B$14,LOWER(N6)) -> 61.018852 | P6: =SUMIFS($J$6:$J$14,$A$6:$A$14,"medium",$B$6:$B$14,LOWER(N6)) -> 61.930282 | Q6: =SUMIFS($J$6:$J$14,$A$6:$A$14,"high",$B$6:$B$14,LOWER(N6)) -> 70.564882
A7: low | B7: paas | C7: 100000 | D7: 0.64437697 | E7: 0.37180697 | F7: 0.23257 | G7: 0.41180697 | H7: 6.4437697 | I7: ESTIMATED_SUPPORTED | J7: =SUMIFS('Cost Breakdown'!$E$6:$E$140,'Cost Breakdown'!$A$6:$A$140,A7,'Cost Breakdown'!$C$6:$C$140,B7) -> 0.64437697 | K7: =J7-D7 -> 0 | L7: =IF(ABS(K7)<0.000001,"OK","CHECK") -> OK | M7: =A7&"|"&B7 -> low|paas | N7: PAAS | O7: =SUMIFS($J$6:$J$14,$A$6:$A$14,"low",$B$6:$B$14,LOWER(N7)) -> 0.64437697 | P7: =SUMIFS($J$6:$J$14,$A$6:$A$14,"medium",$B$6:$B$14,LOWER(N7)) -> 8.9718688 | Q7: =SUMIFS($J$6:$J$14,$A$6:$A$14,"high",$B$6:$B$14,LOWER(N7)) -> 66.233804
A8: low | B8: faas | C8: 100000 | D8: 0.64437697 | E8: 0.37180697 | F8: 0.23257 | G8: 0.41180697 | H8: 6.4437697 | I8: ESTIMATED_SUPPORTED | J8: =SUMIFS('Cost Breakdown'!$E$6:$E$140,'Cost Breakdown'!$A$6:$A$140,A8,'Cost Breakdown'!$C$6:$C$140,B8) -> 0.64437697 | K8: =J8-D8 -> 0 | L8: =IF(ABS(K8)<0.000001,"OK","CHECK") -> OK | M8: =A8&"|"&B8 -> low|faas | N8: FAAS | O8: =SUMIFS($J$6:$J$14,$A$6:$A$14,"low",$B$6:$B$14,LOWER(N8)) -> 0.64437697 | P8: =SUMIFS($J$6:$J$14,$A$6:$A$14,"medium",$B$6:$B$14,LOWER(N8)) -> 8.9718688 | Q8: =SUMIFS($J$6:$J$14,$A$6:$A$14,"high",$B$6:$B$14,LOWER(N8)) -> 66.233804
A9: medium | B9: iaas | C9: 2000000 | D9: 61.930282 | E9: 60.346282 | F9: 1.144 | G9: 60.786282 | H9: 30.965141 | I9: UNVERIFIED | J9: =SUMIFS('Cost Breakdown'!$E$6:$E$140,'Cost Breakdown'!$A$6:$A$140,A9,'Cost Breakdown'!$C$6:$C$140,B9) -> 61.930282 | K9: =J9-D9 -> 0 | L9: =IF(ABS(K9)<0.000001,"OK","CHECK") -> OK | M9: =A9&"|"&B9 -> medium|iaas
A10: medium | B10: paas | C10: 2000000 | D10: 8.9718688 | E10: 7.0278688 | F10: 1.144 | G10: 7.8278688 | H10: 4.4859344 | I10: ESTIMATED_SUPPORTED | J10: =SUMIFS('Cost Breakdown'!$E$6:$E$140,'Cost Breakdown'!$A$6:$A$140,A10,'Cost Breakdown'!$C$6:$C$140,B10) -> 8.9718688 | K10: =J10-D10 -> 0 | L10: =IF(ABS(K10)<0.000001,"OK","CHECK") -> OK | M10: =A10&"|"&B10 -> medium|paas
A11: medium | B11: faas | C11: 2000000 | D11: 8.9718688 | E11: 7.0278688 | F11: 1.144 | G11: 7.8278688 | H11: 4.4859344 | I11: ESTIMATED_SUPPORTED | J11: =SUMIFS('Cost Breakdown'!$E$6:$E$140,'Cost Breakdown'!$A$6:$A$140,A11,'Cost Breakdown'!$C$6:$C$140,B11) -> 8.9718688 | K11: =J11-D11 -> 0 | L11: =IF(ABS(K11)<0.000001,"OK","CHECK") -> OK | M11: =A11&"|"&B11 -> medium|faas
A12: high | B12: iaas | C12: 20000000 | D12: 70.564882 | E12: 60.346282 | F12: 9.7786 | G12: 60.786282 | H12: 3.5282441 | I12: UNVERIFIED | J12: =SUMIFS('Cost Breakdown'!$E$6:$E$140,'Cost Breakdown'!$A$6:$A$140,A12,'Cost Breakdown'!$C$6:$C$140,B12) -> 70.564882 | K12: =J12-D12 -> 0 | L12: =IF(ABS(K12)<0.000001,"OK","CHECK") -> OK | M12: =A12&"|"&B12 -> high|iaas
A13: high | B13: paas | C13: 20000000 | D13: 66.233804 | E13: 48.455204 | F13: 9.7786 | G13: 56.455204 | H13: 3.3116902 | I13: ESTIMATED_SUPPORTED | J13: =SUMIFS('Cost Breakdown'!$E$6:$E$140,'Cost Breakdown'!$A$6:$A$140,A13,'Cost Breakdown'!$C$6:$C$140,B13) -> 66.233804 | K13: =J13-D13 -> 0 | L13: =IF(ABS(K13)<0.000001,"OK","CHECK") -> OK | M13: =A13&"|"&B13 -> high|paas
A14: high | B14: faas | C14: 20000000 | D14: 66.233804 | E14: 48.455204 | F14: 9.7786 | G14: 56.455204 | H14: 3.3116902 | I14: ESTIMATED_SUPPORTED | J14: =SUMIFS('Cost Breakdown'!$E$6:$E$140,'Cost Breakdown'!$A$6:$A$140,A14,'Cost Breakdown'!$C$6:$C$140,B14) -> 66.233804 | K14: =J14-D14 -> 0 | L14: =IF(ABS(K14)<0.000001,"OK","CHECK") -> OK | M14: =A14&"|"&B14 -> high|faas

Sheet Sensitivity
A1: Sensitivity
A2: SIMULATED DATA – NOT REAL CLOUD MEASUREMENTS
A3: results\financial\demo\sensitivity.csv — frozen Python scenario runs; rerun CLI after edits
A5: data_mode | B5: model | C5: parameter | D5: direction | E5: base_usd | F5: total_usd | G5: delta_usd | H5: capacity_status | I5: note
A6: DEMO | B6: iaas | C6: monthly_requests | D6: low | E6: 61.930282 | F6: 61.450582 | G6: -0.4797 | H6: UNVERIFIED
A7: DEMO | B7: iaas | C7: monthly_requests | D7: high | E7: 61.930282 | F7: 62.409982 | G7: 0.4797 | H7: UNVERIFIED
A8: DEMO | B8: iaas | C8: cpu_execution_time | D8: low | E8: 61.930282 | F8: 61.930282 | G8: 0 | H8: UNVERIFIED
A9: DEMO | B9: iaas | C9: cpu_execution_time | D9: high | E9: 61.930282 | F9: 61.930282 | G9: 0 | H9: UNVERIFIED
A10: DEMO | B10: iaas | C10: memory_gib | D10: low | E10: 61.930282 | F10: 61.930282 | G10: 0 | H10: UNVERIFIED | I10: IaaS memory/concurrency change needs a separately priced VM/config
A11: DEMO | B11: iaas | C11: memory_gib | D11: high | E11: 61.930282 | F11: 61.930282 | G11: 0 | H11: UNVERIFIED | I11: IaaS memory/concurrency change needs a separately priced VM/config
A12: DEMO | B12: iaas | C12: read_ratio | D12: low | E12: 61.930282 | F12: 62.188582 | G12: 0.2583 | H12: UNVERIFIED
A13: DEMO | B13: iaas | C13: read_ratio | D13: high | E13: 61.930282 | F13: 61.745782 | G13: -0.1845 | H13: UNVERIFIED
A14: DEMO | B14: iaas | C14: response_bytes | D14: low | E14: 61.930282 | F14: 61.930282 | G14: 0 | H14: UNVERIFIED
A15: DEMO | B15: iaas | C15: response_bytes | D15: high | E15: 61.930282 | F15: 61.930282 | G15: 0 | H15: UNVERIFIED
A16: DEMO | B16: iaas | C16: concurrency | D16: low | E16: 61.930282 | F16: 61.930282 | G16: 0 | H16: UNVERIFIED | I16: IaaS memory/concurrency change needs a separately priced VM/config
A17: DEMO | B17: iaas | C17: concurrency | D17: high | E17: 61.930282 | F17: 61.930282 | G17: 0 | H17: UNVERIFIED | I17: IaaS memory/concurrency change needs a separately priced VM/config
A18: DEMO | B18: iaas | C18: peak_to_average | D18: low | E18: 61.930282 | F18: 61.930282 | G18: 0 | H18: UNVERIFIED
A19: DEMO | B19: iaas | C19: peak_to_average | D19: high | E19: 61.930282 | F19: 61.930282 | G19: 0 | H19: UNVERIFIED
A20: DEMO | B20: iaas | C20: active_hours_per_day | D20: low | E20: 61.930282 | F20: 61.930282 | G20: 0 | H20: UNVERIFIED
A21: DEMO | B21: iaas | C21: active_hours_per_day | D21: high | E21: 61.930282 | F21: 61.930282 | G21: 0 | H21: UNVERIFIED
A22: DEMO | B22: iaas | C22: min_instances | D22: low | E22: 61.930282 | F22: 61.930282 | G22: 0 | H22: UNVERIFIED | I22: IaaS memory/concurrency change needs a separately priced VM/config
A23: DEMO | B23: iaas | C23: min_instances | D23: high | E23: 61.930282 | F23: 61.930282 | G23: 0 | H23: UNVERIFIED | I23: IaaS memory/concurrency change needs a separately priced VM/config
A24: DEMO | B24: iaas | C24: price_multiplier | D24: low | E24: 61.930282 | F24: 30.965141 | G24: -30.965141 | H24: UNVERIFIED
A25: DEMO | B25: iaas | C25: price_multiplier | D25: high | E25: 61.930282 | F25: 92.895423 | G25: 30.965141 | H25: UNVERIFIED
A26: DEMO | B26: iaas | C26: labor_usd_per_hour | D26: low | E26: 61.930282 | F26: 61.930282 | G26: 0 | H26: UNVERIFIED
A27: DEMO | B27: iaas | C27: labor_usd_per_hour | D27: high | E27: 61.930282 | F27: 61.930282 | G27: 0 | H27: UNVERIFIED
A28: DEMO | B28: paas | C28: monthly_requests | D28: low | E28: 8.9718688 | F28: 4.674445 | G28: -4.2974237 | H28: ESTIMATED_SUPPORTED
A29: DEMO | B29: paas | C29: monthly_requests | D29: high | E29: 8.9718688 | F29: 13.09608 | G29: 4.1242111 | H29: ESTIMATED_SUPPORTED
A30: DEMO | B30: paas | C30: cpu_execution_time | D30: low | E30: 8.9718688 | F30: 8.9718688 | G30: 0 | H30: ESTIMATED_SUPPORTED
A31: DEMO | B31: paas | C31: cpu_execution_time | D31: high | E31: 8.9718688 | F31: 8.9718688 | G31: 0 | H31: ESTIMATED_SUPPORTED
A32: DEMO | B32: paas | C32: memory_gib | D32: low | E32: 8.9718688 | F32: 8.6403655 | G32: -0.33150324 | H32: ESTIMATED_SUPPORTED
A33: DEMO | B33: paas | C33: memory_gib | D33: high | E33: 8.9718688 | F33: 9.303372 | G33: 0.33150324 | H33: ESTIMATED_SUPPORTED
A34: DEMO | B34: paas | C34: read_ratio | D34: low | E34: 8.9718688 | F34: 9.2301688 | G34: 0.2583 | H34: ESTIMATED_SUPPORTED
A35: DEMO | B35: paas | C35: read_ratio | D35: high | E35: 8.9718688 | F35: 8.7873688 | G35: -0.1845 | H35: ESTIMATED_SUPPORTED
... A71: DEMO | B71: faas | C71: labor_usd_per_hour | D71: high | E71: 8.9718688 | F71: 8.9718688 | G71: 0 | H71: ESTIMATED_SUPPORTED

Sheet Pricing Sources
A1: Pricing Sources
A2: SIMULATED DATA – NOT REAL CLOUD MEASUREMENTS
A3: configs/pricing_catalog.yaml; reports/sources/source_manifest.json
A5: key | B5: service | C5: sku_description | D5: unit | E5: unit_price_usd | F5: region | G5: retrieved_date | H5: effective_date | I5: source_url | J5: status
A6: vm_hour | B6: Compute Engine | C6: E2 standard 2 vCPU 8 GiB on-demand Linux | D6: VM-hour | E6: 0.08266614 | F6: asia-southeast1 | G6: 2026-10-31 | I6: https://cloud.google.com/products/compute/pricing/general-purpose | J6: PUBLIC_LIST_PRICE_SNAPSHOT
A7: run_cpu_request | B7: Cloud Run | C7: Active CPU request-based Singapore | D7: vCPU-second | E7: 3.36e-05 | F7: asia-southeast1 | G7: 2026-10-31 | I7: https://cloud.google.com/run/pricing | J7: PUBLIC_LIST_PRICE_SNAPSHOT
A8: run_memory_request | B8: Cloud Run | C8: Active memory request-based Singapore | D8: GiB-second | E8: 3.5e-06 | F8: asia-southeast1 | G8: 2026-10-31 | I8: https://cloud.google.com/run/pricing | J8: PUBLIC_LIST_PRICE_SNAPSHOT
